[2024-05-22T01:01:41.454+0000] {local_task_job_runner.py:120} INFO - ::group::Pre task execution logs
[2024-05-22T01:01:41.533+0000] {taskinstance.py:2076} INFO - Dependencies all met for dep_context=non-requeueable deps ti=<TaskInstance: kaggle_dataset.extraccion manual__2024-05-21T22:05:48.748499+00:00 [queued]>
[2024-05-22T01:01:41.579+0000] {taskinstance.py:2076} INFO - Dependencies all met for dep_context=requeueable deps ti=<TaskInstance: kaggle_dataset.extraccion manual__2024-05-21T22:05:48.748499+00:00 [queued]>
[2024-05-22T01:01:41.583+0000] {taskinstance.py:2306} INFO - Starting attempt 32 of 36
[2024-05-22T01:01:41.957+0000] {taskinstance.py:2330} INFO - Executing <Task(PythonOperator): extraccion> on 2024-05-21 22:05:48.748499+00:00
[2024-05-22T01:01:41.982+0000] {warnings.py:110} WARNING - /home/***/.local/lib/python3.12/site-packages/***/task/task_runner/standard_task_runner.py:61: DeprecationWarning: This process (pid=143) is multi-threaded, use of fork() may lead to deadlocks in the child.
  pid = os.fork()

[2024-05-22T01:01:41.988+0000] {standard_task_runner.py:63} INFO - Started process 167 to run task
[2024-05-22T01:01:41.984+0000] {standard_task_runner.py:90} INFO - Running: ['***', 'tasks', 'run', 'kaggle_dataset', 'extraccion', 'manual__2024-05-21T22:05:48.748499+00:00', '--job-id', '49', '--raw', '--subdir', 'DAGS_FOLDER/kaggle_dataset.py', '--cfg-path', '/tmp/tmpq1stq6nh']
[2024-05-22T01:01:41.991+0000] {standard_task_runner.py:91} INFO - Job 49: Subtask extraccion
[2024-05-22T01:01:42.152+0000] {task_command.py:426} INFO - Running <TaskInstance: kaggle_dataset.extraccion manual__2024-05-21T22:05:48.748499+00:00 [running]> on host 54af258cbbe3
[2024-05-22T01:01:42.374+0000] {taskinstance.py:2648} INFO - Exporting env vars: AIRFLOW_CTX_DAG_OWNER='***' AIRFLOW_CTX_DAG_ID='kaggle_dataset' AIRFLOW_CTX_TASK_ID='extraccion' AIRFLOW_CTX_EXECUTION_DATE='2024-05-21T22:05:48.748499+00:00' AIRFLOW_CTX_TRY_NUMBER='32' AIRFLOW_CTX_DAG_RUN_ID='manual__2024-05-21T22:05:48.748499+00:00'
[2024-05-22T01:01:42.378+0000] {taskinstance.py:430} INFO - ::endgroup::
[2024-05-22T01:01:42.440+0000] {logging_mixin.py:188} INFO - Warning: Your Kaggle API key is readable by other users on this system! To fix this, you can run 'chmod 600 /home/***/.kaggle/kaggle.json'
[2024-05-22T01:01:47.007+0000] {taskinstance.py:441} INFO - ::group::Post task execution logs
[2024-05-22T01:01:47.010+0000] {taskinstance.py:2905} ERROR - Task failed with exception
Traceback (most recent call last):
  File "/home/airflow/.local/lib/python3.12/site-packages/airflow/models/taskinstance.py", line 465, in _execute_task
    result = _execute_callable(context=context, **execute_callable_kwargs)
             ^^^^^^^^^^^^^^^^^^^^^^^^^^^^^^^^^^^^^^^^^^^^^^^^^^^^^^^^^^^^^
  File "/home/airflow/.local/lib/python3.12/site-packages/airflow/models/taskinstance.py", line 432, in _execute_callable
    return execute_callable(context=context, **execute_callable_kwargs)
           ^^^^^^^^^^^^^^^^^^^^^^^^^^^^^^^^^^^^^^^^^^^^^^^^^^^^^^^^^^^^
  File "/home/airflow/.local/lib/python3.12/site-packages/airflow/models/baseoperator.py", line 400, in wrapper
    return func(self, *args, **kwargs)
           ^^^^^^^^^^^^^^^^^^^^^^^^^^^
  File "/home/airflow/.local/lib/python3.12/site-packages/airflow/operators/python.py", line 235, in execute
    return_value = self.execute_callable()
                   ^^^^^^^^^^^^^^^^^^^^^^^
  File "/home/airflow/.local/lib/python3.12/site-packages/airflow/operators/python.py", line 252, in execute_callable
    return self.python_callable(*self.op_args, **self.op_kwargs)
           ^^^^^^^^^^^^^^^^^^^^^^^^^^^^^^^^^^^^^^^^^^^^^^^^^^^^^
  File "/opt/airflow/dags/kaggle_dataset.py", line 27, in extract_task
    subprocess.run("unzip global-economy-indicators.zip -d ./data", shell=True, check=True)
  File "/usr/local/lib/python3.12/subprocess.py", line 571, in run
    raise CalledProcessError(retcode, process.args,
subprocess.CalledProcessError: Command 'unzip global-economy-indicators.zip -d ./data' returned non-zero exit status 127.
[2024-05-22T01:01:47.049+0000] {taskinstance.py:1206} INFO - Marking task as UP_FOR_RETRY. dag_id=kaggle_dataset, task_id=extraccion, run_id=manual__2024-05-21T22:05:48.748499+00:00, execution_date=20240521T220548, start_date=20240522T010141, end_date=20240522T010147
[2024-05-22T01:01:47.086+0000] {standard_task_runner.py:110} ERROR - Failed to execute job 49 for task extraccion (Command 'unzip global-economy-indicators.zip -d ./data' returned non-zero exit status 127.; 167)
[2024-05-22T01:01:47.118+0000] {local_task_job_runner.py:240} INFO - Task exited with return code 1
[2024-05-22T01:01:47.188+0000] {taskinstance.py:3498} INFO - 0 downstream tasks scheduled from follow-on schedule check
[2024-05-22T01:01:47.194+0000] {local_task_job_runner.py:222} INFO - ::endgroup::
