[2024-05-22T00:51:09.228+0000] {local_task_job_runner.py:120} INFO - ::group::Pre task execution logs
[2024-05-22T00:51:09.291+0000] {taskinstance.py:2076} INFO - Dependencies all met for dep_context=non-requeueable deps ti=<TaskInstance: kaggle_dataset.extraccion manual__2024-05-21T22:05:48.748499+00:00 [queued]>
[2024-05-22T00:51:09.322+0000] {taskinstance.py:2076} INFO - Dependencies all met for dep_context=requeueable deps ti=<TaskInstance: kaggle_dataset.extraccion manual__2024-05-21T22:05:48.748499+00:00 [queued]>
[2024-05-22T00:51:09.324+0000] {taskinstance.py:2306} INFO - Starting attempt 28 of 32
[2024-05-22T00:51:09.615+0000] {taskinstance.py:2330} INFO - Executing <Task(PythonOperator): extraccion> on 2024-05-21 22:05:48.748499+00:00
[2024-05-22T00:51:09.633+0000] {warnings.py:110} WARNING - /home/***/.local/lib/python3.12/site-packages/***/task/task_runner/standard_task_runner.py:61: DeprecationWarning: This process (pid=124) is multi-threaded, use of fork() may lead to deadlocks in the child.
  pid = os.fork()

[2024-05-22T00:51:09.638+0000] {standard_task_runner.py:63} INFO - Started process 148 to run task
[2024-05-22T00:51:09.636+0000] {standard_task_runner.py:90} INFO - Running: ['***', 'tasks', 'run', 'kaggle_dataset', 'extraccion', 'manual__2024-05-21T22:05:48.748499+00:00', '--job-id', '43', '--raw', '--subdir', 'DAGS_FOLDER/kaggle_dataset.py', '--cfg-path', '/tmp/tmpiv7nabzw']
[2024-05-22T00:51:09.642+0000] {standard_task_runner.py:91} INFO - Job 43: Subtask extraccion
[2024-05-22T00:51:09.778+0000] {task_command.py:426} INFO - Running <TaskInstance: kaggle_dataset.extraccion manual__2024-05-21T22:05:48.748499+00:00 [running]> on host 5b8d782b22fb
[2024-05-22T00:51:09.999+0000] {taskinstance.py:2648} INFO - Exporting env vars: AIRFLOW_CTX_DAG_OWNER='***' AIRFLOW_CTX_DAG_ID='kaggle_dataset' AIRFLOW_CTX_TASK_ID='extraccion' AIRFLOW_CTX_EXECUTION_DATE='2024-05-21T22:05:48.748499+00:00' AIRFLOW_CTX_TRY_NUMBER='28' AIRFLOW_CTX_DAG_RUN_ID='manual__2024-05-21T22:05:48.748499+00:00'
[2024-05-22T00:51:10.002+0000] {taskinstance.py:430} INFO - ::endgroup::
[2024-05-22T00:51:10.059+0000] {logging_mixin.py:188} INFO - Warning: Your Kaggle API key is readable by other users on this system! To fix this, you can run 'chmod 600 /home/***/.kaggle/kaggle.json'
[2024-05-22T00:51:10.079+0000] {taskinstance.py:441} INFO - ::group::Post task execution logs
[2024-05-22T00:51:10.082+0000] {taskinstance.py:2905} ERROR - Task failed with exception
Traceback (most recent call last):
  File "/home/airflow/.local/lib/python3.12/site-packages/airflow/models/taskinstance.py", line 465, in _execute_task
    result = _execute_callable(context=context, **execute_callable_kwargs)
             ^^^^^^^^^^^^^^^^^^^^^^^^^^^^^^^^^^^^^^^^^^^^^^^^^^^^^^^^^^^^^
  File "/home/airflow/.local/lib/python3.12/site-packages/airflow/models/taskinstance.py", line 432, in _execute_callable
    return execute_callable(context=context, **execute_callable_kwargs)
           ^^^^^^^^^^^^^^^^^^^^^^^^^^^^^^^^^^^^^^^^^^^^^^^^^^^^^^^^^^^^
  File "/home/airflow/.local/lib/python3.12/site-packages/airflow/models/baseoperator.py", line 400, in wrapper
    return func(self, *args, **kwargs)
           ^^^^^^^^^^^^^^^^^^^^^^^^^^^
  File "/home/airflow/.local/lib/python3.12/site-packages/airflow/operators/python.py", line 235, in execute
    return_value = self.execute_callable()
                   ^^^^^^^^^^^^^^^^^^^^^^^
  File "/home/airflow/.local/lib/python3.12/site-packages/airflow/operators/python.py", line 252, in execute_callable
    return self.python_callable(*self.op_args, **self.op_kwargs)
           ^^^^^^^^^^^^^^^^^^^^^^^^^^^^^^^^^^^^^^^^^^^^^^^^^^^^^
  File "/opt/airflow/dags/kaggle_dataset.py", line 26, in extract_task
    subprocess.run("kaggle datasets download -d prasad22/global-economy-indicators", shell=True, Check=True)
  File "/usr/local/lib/python3.12/subprocess.py", line 548, in run
    with Popen(*popenargs, **kwargs) as process:
         ^^^^^^^^^^^^^^^^^^^^^^^^^^^
TypeError: Popen.__init__() got an unexpected keyword argument 'Check'
[2024-05-22T00:51:10.117+0000] {taskinstance.py:1206} INFO - Marking task as UP_FOR_RETRY. dag_id=kaggle_dataset, task_id=extraccion, run_id=manual__2024-05-21T22:05:48.748499+00:00, execution_date=20240521T220548, start_date=20240522T005109, end_date=20240522T005110
[2024-05-22T00:51:10.150+0000] {standard_task_runner.py:110} ERROR - Failed to execute job 43 for task extraccion (Popen.__init__() got an unexpected keyword argument 'Check'; 148)
[2024-05-22T00:51:10.178+0000] {local_task_job_runner.py:240} INFO - Task exited with return code 1
[2024-05-22T00:51:10.254+0000] {taskinstance.py:3498} INFO - 0 downstream tasks scheduled from follow-on schedule check
[2024-05-22T00:51:10.261+0000] {local_task_job_runner.py:222} INFO - ::endgroup::
