[2024-05-21T23:32:37.258+0000] {task_context_logger.py:104} ERROR - Executor reports task instance <TaskInstance: kaggle_dataset.extraccion manual__2024-05-21T22:05:48.748499+00:00 [queued]> finished (failed) although the task says it's queued. (Info: None) Was the task killed externally?
