[2024-05-22T00:32:15.428+0000] {local_task_job_runner.py:120} INFO - ::group::Pre task execution logs
[2024-05-22T00:32:15.497+0000] {taskinstance.py:2076} INFO - Dependencies all met for dep_context=non-requeueable deps ti=<TaskInstance: kaggle_dataset.extraccion manual__2024-05-21T22:05:48.748499+00:00 [queued]>
[2024-05-22T00:32:15.533+0000] {taskinstance.py:2076} INFO - Dependencies all met for dep_context=requeueable deps ti=<TaskInstance: kaggle_dataset.extraccion manual__2024-05-21T22:05:48.748499+00:00 [queued]>
[2024-05-22T00:32:15.537+0000] {taskinstance.py:2306} INFO - Starting attempt 18 of 22
[2024-05-22T00:32:15.846+0000] {taskinstance.py:2330} INFO - Executing <Task(PythonOperator): extraccion> on 2024-05-21 22:05:48.748499+00:00
[2024-05-22T00:32:15.863+0000] {warnings.py:110} WARNING - /home/***/.local/lib/python3.12/site-packages/***/task/task_runner/standard_task_runner.py:61: DeprecationWarning: This process (pid=331) is multi-threaded, use of fork() may lead to deadlocks in the child.
  pid = os.fork()

[2024-05-22T00:32:15.870+0000] {standard_task_runner.py:63} INFO - Started process 355 to run task
[2024-05-22T00:32:15.869+0000] {standard_task_runner.py:90} INFO - Running: ['***', 'tasks', 'run', 'kaggle_dataset', 'extraccion', 'manual__2024-05-21T22:05:48.748499+00:00', '--job-id', '33', '--raw', '--subdir', 'DAGS_FOLDER/kaggle_dataset.py', '--cfg-path', '/tmp/tmpt_x8kgn_']
[2024-05-22T00:32:15.876+0000] {standard_task_runner.py:91} INFO - Job 33: Subtask extraccion
[2024-05-22T00:32:16.008+0000] {task_command.py:426} INFO - Running <TaskInstance: kaggle_dataset.extraccion manual__2024-05-21T22:05:48.748499+00:00 [running]> on host 096f5d962783
[2024-05-22T00:32:16.257+0000] {taskinstance.py:2648} INFO - Exporting env vars: AIRFLOW_CTX_DAG_OWNER='***' AIRFLOW_CTX_DAG_ID='kaggle_dataset' AIRFLOW_CTX_TASK_ID='extraccion' AIRFLOW_CTX_EXECUTION_DATE='2024-05-21T22:05:48.748499+00:00' AIRFLOW_CTX_TRY_NUMBER='18' AIRFLOW_CTX_DAG_RUN_ID='manual__2024-05-21T22:05:48.748499+00:00'
[2024-05-22T00:32:16.261+0000] {taskinstance.py:430} INFO - ::endgroup::
[2024-05-22T00:32:16.323+0000] {logging_mixin.py:188} INFO - Warning: Your Kaggle API key is readable by other users on this system! To fix this, you can run 'chmod 600 /home/***/.kaggle/kaggle.json'
[2024-05-22T00:32:19.368+0000] {taskinstance.py:441} INFO - ::group::Post task execution logs
[2024-05-22T00:32:19.371+0000] {taskinstance.py:2905} ERROR - Task failed with exception
Traceback (most recent call last):
  File "/home/airflow/.local/lib/python3.12/site-packages/airflow/models/taskinstance.py", line 465, in _execute_task
    result = _execute_callable(context=context, **execute_callable_kwargs)
             ^^^^^^^^^^^^^^^^^^^^^^^^^^^^^^^^^^^^^^^^^^^^^^^^^^^^^^^^^^^^^
  File "/home/airflow/.local/lib/python3.12/site-packages/airflow/models/taskinstance.py", line 432, in _execute_callable
    return execute_callable(context=context, **execute_callable_kwargs)
           ^^^^^^^^^^^^^^^^^^^^^^^^^^^^^^^^^^^^^^^^^^^^^^^^^^^^^^^^^^^^
  File "/home/airflow/.local/lib/python3.12/site-packages/airflow/models/baseoperator.py", line 400, in wrapper
    return func(self, *args, **kwargs)
           ^^^^^^^^^^^^^^^^^^^^^^^^^^^
  File "/home/airflow/.local/lib/python3.12/site-packages/airflow/operators/python.py", line 235, in execute
    return_value = self.execute_callable()
                   ^^^^^^^^^^^^^^^^^^^^^^^
  File "/home/airflow/.local/lib/python3.12/site-packages/airflow/operators/python.py", line 252, in execute_callable
    return self.python_callable(*self.op_args, **self.op_kwargs)
           ^^^^^^^^^^^^^^^^^^^^^^^^^^^^^^^^^^^^^^^^^^^^^^^^^^^^^
  File "/opt/airflow/dags/kaggle_dataset.py", line 30, in extract_task
    resultado1 = subprocess.run(comando_1, shell=True, check=True)
                 ^^^^^^^^^^^^^^^^^^^^^^^^^^^^^^^^^^^^^^^^^^^^^^^^^
  File "/usr/local/lib/python3.12/subprocess.py", line 571, in run
    raise CalledProcessError(retcode, process.args,
subprocess.CalledProcessError: Command 'kaggle datasets download -d datasets/prasad22/global-economy-indicators' returned non-zero exit status 1.
[2024-05-22T00:32:19.409+0000] {taskinstance.py:1206} INFO - Marking task as UP_FOR_RETRY. dag_id=kaggle_dataset, task_id=extraccion, run_id=manual__2024-05-21T22:05:48.748499+00:00, execution_date=20240521T220548, start_date=20240522T003215, end_date=20240522T003219
[2024-05-22T00:32:19.454+0000] {standard_task_runner.py:110} ERROR - Failed to execute job 33 for task extraccion (Command 'kaggle datasets download -d datasets/prasad22/global-economy-indicators' returned non-zero exit status 1.; 355)
[2024-05-22T00:32:19.512+0000] {local_task_job_runner.py:240} INFO - Task exited with return code 1
[2024-05-22T00:32:19.590+0000] {taskinstance.py:3498} INFO - 0 downstream tasks scheduled from follow-on schedule check
[2024-05-22T00:32:19.596+0000] {local_task_job_runner.py:222} INFO - ::endgroup::
