[2024-05-22T22:09:42.299+0000] {local_task_job_runner.py:120} INFO - ::group::Pre task execution logs
[2024-05-22T22:09:42.337+0000] {taskinstance.py:2076} INFO - Dependencies all met for dep_context=non-requeueable deps ti=<TaskInstance: kaggle_dataset.transformacion manual__2024-05-22T22:09:25.534916+00:00 [queued]>
[2024-05-22T22:09:42.352+0000] {taskinstance.py:2076} INFO - Dependencies all met for dep_context=requeueable deps ti=<TaskInstance: kaggle_dataset.transformacion manual__2024-05-22T22:09:25.534916+00:00 [queued]>
[2024-05-22T22:09:42.354+0000] {taskinstance.py:2306} INFO - Starting attempt 1 of 5
[2024-05-22T22:09:42.377+0000] {taskinstance.py:2330} INFO - Executing <Task(PythonOperator): transformacion> on 2024-05-22 22:09:25.534916+00:00
[2024-05-22T22:09:42.389+0000] {warnings.py:110} WARNING - /home/***/.local/lib/python3.12/site-packages/***/task/task_runner/standard_task_runner.py:61: DeprecationWarning: This process (pid=287) is multi-threaded, use of fork() may lead to deadlocks in the child.
  pid = os.fork()

[2024-05-22T22:09:42.393+0000] {standard_task_runner.py:63} INFO - Started process 311 to run task
[2024-05-22T22:09:42.390+0000] {standard_task_runner.py:90} INFO - Running: ['***', 'tasks', 'run', 'kaggle_dataset', 'transformacion', 'manual__2024-05-22T22:09:25.534916+00:00', '--job-id', '4', '--raw', '--subdir', 'DAGS_FOLDER/kaggle_dataset.py', '--cfg-path', '/tmp/tmpachl1fbv']
[2024-05-22T22:09:42.394+0000] {standard_task_runner.py:91} INFO - Job 4: Subtask transformacion
[2024-05-22T22:09:42.465+0000] {task_command.py:426} INFO - Running <TaskInstance: kaggle_dataset.transformacion manual__2024-05-22T22:09:25.534916+00:00 [running]> on host 3943db1ddae8
[2024-05-22T22:09:42.602+0000] {taskinstance.py:2648} INFO - Exporting env vars: AIRFLOW_CTX_DAG_OWNER='***' AIRFLOW_CTX_DAG_ID='kaggle_dataset' AIRFLOW_CTX_TASK_ID='transformacion' AIRFLOW_CTX_EXECUTION_DATE='2024-05-22T22:09:25.534916+00:00' AIRFLOW_CTX_TRY_NUMBER='1' AIRFLOW_CTX_DAG_RUN_ID='manual__2024-05-22T22:09:25.534916+00:00'
[2024-05-22T22:09:42.606+0000] {taskinstance.py:430} INFO - ::endgroup::
[2024-05-22T22:09:42.631+0000] {taskinstance.py:441} INFO - ::group::Post task execution logs
[2024-05-22T22:09:42.633+0000] {taskinstance.py:2905} ERROR - Task failed with exception
Traceback (most recent call last):
  File "/home/airflow/.local/lib/python3.12/site-packages/airflow/models/taskinstance.py", line 465, in _execute_task
    result = _execute_callable(context=context, **execute_callable_kwargs)
             ^^^^^^^^^^^^^^^^^^^^^^^^^^^^^^^^^^^^^^^^^^^^^^^^^^^^^^^^^^^^^
  File "/home/airflow/.local/lib/python3.12/site-packages/airflow/models/taskinstance.py", line 432, in _execute_callable
    return execute_callable(context=context, **execute_callable_kwargs)
           ^^^^^^^^^^^^^^^^^^^^^^^^^^^^^^^^^^^^^^^^^^^^^^^^^^^^^^^^^^^^
  File "/home/airflow/.local/lib/python3.12/site-packages/airflow/models/baseoperator.py", line 400, in wrapper
    return func(self, *args, **kwargs)
           ^^^^^^^^^^^^^^^^^^^^^^^^^^^
  File "/home/airflow/.local/lib/python3.12/site-packages/airflow/operators/python.py", line 235, in execute
    return_value = self.execute_callable()
                   ^^^^^^^^^^^^^^^^^^^^^^^
  File "/home/airflow/.local/lib/python3.12/site-packages/airflow/operators/python.py", line 252, in execute_callable
    return self.python_callable(*self.op_args, **self.op_kwargs)
           ^^^^^^^^^^^^^^^^^^^^^^^^^^^^^^^^^^^^^^^^^^^^^^^^^^^^^
  File "/opt/airflow/dags/kaggle_dataset.py", line 39, in transform_task
    df = pd.read_csv('global-economy-indicators.zip')
         ^^^^^^^^^^^^^^^^^^^^^^^^^^^^^^^^^^^^^^^^^^^^
  File "/home/airflow/.local/lib/python3.12/site-packages/pandas/io/parsers/readers.py", line 948, in read_csv
    return _read(filepath_or_buffer, kwds)
           ^^^^^^^^^^^^^^^^^^^^^^^^^^^^^^^
  File "/home/airflow/.local/lib/python3.12/site-packages/pandas/io/parsers/readers.py", line 611, in _read
    parser = TextFileReader(filepath_or_buffer, **kwds)
             ^^^^^^^^^^^^^^^^^^^^^^^^^^^^^^^^^^^^^^^^^^
  File "/home/airflow/.local/lib/python3.12/site-packages/pandas/io/parsers/readers.py", line 1448, in __init__
    self._engine = self._make_engine(f, self.engine)
                   ^^^^^^^^^^^^^^^^^^^^^^^^^^^^^^^^^
  File "/home/airflow/.local/lib/python3.12/site-packages/pandas/io/parsers/readers.py", line 1705, in _make_engine
    self.handles = get_handle(
                   ^^^^^^^^^^^
  File "/home/airflow/.local/lib/python3.12/site-packages/pandas/io/common.py", line 784, in get_handle
    handle = _BytesZipFile(
             ^^^^^^^^^^^^^^
  File "/home/airflow/.local/lib/python3.12/site-packages/pandas/io/common.py", line 1027, in __init__
    self.buffer: zipfile.ZipFile = zipfile.ZipFile(  # type: ignore[assignment]
                                   ^^^^^^^^^^^^^^^^^^^^^^^^^^^^^^^^^^^^^^^^^^^^
  File "/usr/local/lib/python3.12/zipfile/__init__.py", line 1331, in __init__
    self.fp = io.open(file, filemode)
              ^^^^^^^^^^^^^^^^^^^^^^^
FileNotFoundError: [Errno 2] No such file or directory: 'global-economy-indicators.zip'
[2024-05-22T22:09:42.657+0000] {taskinstance.py:1206} INFO - Marking task as UP_FOR_RETRY. dag_id=kaggle_dataset, task_id=transformacion, run_id=manual__2024-05-22T22:09:25.534916+00:00, execution_date=20240522T220925, start_date=20240522T220942, end_date=20240522T220942
[2024-05-22T22:09:42.681+0000] {standard_task_runner.py:110} ERROR - Failed to execute job 4 for task transformacion ([Errno 2] No such file or directory: 'global-economy-indicators.zip'; 311)
[2024-05-22T22:09:42.729+0000] {local_task_job_runner.py:240} INFO - Task exited with return code 1
[2024-05-22T22:09:42.764+0000] {taskinstance.py:3498} INFO - 0 downstream tasks scheduled from follow-on schedule check
[2024-05-22T22:09:42.768+0000] {local_task_job_runner.py:222} INFO - ::endgroup::
