[2024-05-22T01:28:50.246+0000] {local_task_job_runner.py:120} INFO - ::group::Pre task execution logs
[2024-05-22T01:28:50.316+0000] {taskinstance.py:2076} INFO - Dependencies all met for dep_context=non-requeueable deps ti=<TaskInstance: kaggle_dataset.extraccion manual__2024-05-22T01:16:10.864259+00:00 [queued]>
[2024-05-22T01:28:50.340+0000] {taskinstance.py:2076} INFO - Dependencies all met for dep_context=requeueable deps ti=<TaskInstance: kaggle_dataset.extraccion manual__2024-05-22T01:16:10.864259+00:00 [queued]>
[2024-05-22T01:28:50.343+0000] {taskinstance.py:2306} INFO - Starting attempt 5 of 9
[2024-05-22T01:28:50.650+0000] {taskinstance.py:2330} INFO - Executing <Task(PythonOperator): extraccion> on 2024-05-22 01:16:10.864259+00:00
[2024-05-22T01:28:50.664+0000] {warnings.py:110} WARNING - /home/***/.local/lib/python3.12/site-packages/***/task/task_runner/standard_task_runner.py:61: DeprecationWarning: This process (pid=696) is multi-threaded, use of fork() may lead to deadlocks in the child.
  pid = os.fork()

[2024-05-22T01:28:50.667+0000] {standard_task_runner.py:63} INFO - Started process 720 to run task
[2024-05-22T01:28:50.669+0000] {standard_task_runner.py:90} INFO - Running: ['***', 'tasks', 'run', 'kaggle_dataset', 'extraccion', 'manual__2024-05-22T01:16:10.864259+00:00', '--job-id', '15', '--raw', '--subdir', 'DAGS_FOLDER/kaggle_dataset.py', '--cfg-path', '/tmp/tmp3xyl4plx']
[2024-05-22T01:28:50.675+0000] {standard_task_runner.py:91} INFO - Job 15: Subtask extraccion
[2024-05-22T01:28:50.789+0000] {task_command.py:426} INFO - Running <TaskInstance: kaggle_dataset.extraccion manual__2024-05-22T01:16:10.864259+00:00 [running]> on host b17c52120858
[2024-05-22T01:28:51.025+0000] {taskinstance.py:2648} INFO - Exporting env vars: AIRFLOW_CTX_DAG_OWNER='***' AIRFLOW_CTX_DAG_ID='kaggle_dataset' AIRFLOW_CTX_TASK_ID='extraccion' AIRFLOW_CTX_EXECUTION_DATE='2024-05-22T01:16:10.864259+00:00' AIRFLOW_CTX_TRY_NUMBER='5' AIRFLOW_CTX_DAG_RUN_ID='manual__2024-05-22T01:16:10.864259+00:00'
[2024-05-22T01:28:51.029+0000] {taskinstance.py:430} INFO - ::endgroup::
[2024-05-22T01:28:51.091+0000] {logging_mixin.py:188} INFO - Warning: Your Kaggle API key is readable by other users on this system! To fix this, you can run 'chmod 600 /home/***/.kaggle/kaggle.json'
[2024-05-22T01:28:55.418+0000] {taskinstance.py:441} INFO - ::group::Post task execution logs
[2024-05-22T01:28:55.421+0000] {taskinstance.py:2905} ERROR - Task failed with exception
Traceback (most recent call last):
  File "/home/airflow/.local/lib/python3.12/site-packages/airflow/models/taskinstance.py", line 465, in _execute_task
    result = _execute_callable(context=context, **execute_callable_kwargs)
             ^^^^^^^^^^^^^^^^^^^^^^^^^^^^^^^^^^^^^^^^^^^^^^^^^^^^^^^^^^^^^
  File "/home/airflow/.local/lib/python3.12/site-packages/airflow/models/taskinstance.py", line 432, in _execute_callable
    return execute_callable(context=context, **execute_callable_kwargs)
           ^^^^^^^^^^^^^^^^^^^^^^^^^^^^^^^^^^^^^^^^^^^^^^^^^^^^^^^^^^^^
  File "/home/airflow/.local/lib/python3.12/site-packages/airflow/models/baseoperator.py", line 400, in wrapper
    return func(self, *args, **kwargs)
           ^^^^^^^^^^^^^^^^^^^^^^^^^^^
  File "/home/airflow/.local/lib/python3.12/site-packages/airflow/operators/python.py", line 235, in execute
    return_value = self.execute_callable()
                   ^^^^^^^^^^^^^^^^^^^^^^^
  File "/home/airflow/.local/lib/python3.12/site-packages/airflow/operators/python.py", line 252, in execute_callable
    return self.python_callable(*self.op_args, **self.op_kwargs)
           ^^^^^^^^^^^^^^^^^^^^^^^^^^^^^^^^^^^^^^^^^^^^^^^^^^^^^
  File "/opt/airflow/dags/kaggle_dataset.py", line 32, in extract_task
    with ZipFile(filename, 'r') as zip:
         ^^^^^^^^^^^^^^^^^^^^^^
  File "/usr/local/lib/python3.12/zipfile/__init__.py", line 1331, in __init__
    self.fp = io.open(file, filemode)
              ^^^^^^^^^^^^^^^^^^^^^^^
FileNotFoundError: [Errno 2] No such file or directory: '/data/global-economy-indicators.zip'
[2024-05-22T01:28:55.463+0000] {taskinstance.py:1206} INFO - Marking task as UP_FOR_RETRY. dag_id=kaggle_dataset, task_id=extraccion, run_id=manual__2024-05-22T01:16:10.864259+00:00, execution_date=20240522T011610, start_date=20240522T012850, end_date=20240522T012855
[2024-05-22T01:28:55.515+0000] {standard_task_runner.py:110} ERROR - Failed to execute job 15 for task extraccion ([Errno 2] No such file or directory: '/data/global-economy-indicators.zip'; 720)
[2024-05-22T01:28:55.556+0000] {local_task_job_runner.py:240} INFO - Task exited with return code 1
[2024-05-22T01:28:55.624+0000] {taskinstance.py:3498} INFO - 0 downstream tasks scheduled from follow-on schedule check
[2024-05-22T01:28:55.631+0000] {local_task_job_runner.py:222} INFO - ::endgroup::
