[2024-05-23T00:49:40.971+0000] {local_task_job_runner.py:120} INFO - ::group::Pre task execution logs
[2024-05-23T00:49:41.031+0000] {taskinstance.py:2076} INFO - Dependencies all met for dep_context=non-requeueable deps ti=<TaskInstance: kaggle_dataset.load_task manual__2024-05-22T22:09:25.534916+00:00 [queued]>
[2024-05-23T00:49:41.058+0000] {taskinstance.py:2076} INFO - Dependencies all met for dep_context=requeueable deps ti=<TaskInstance: kaggle_dataset.load_task manual__2024-05-22T22:09:25.534916+00:00 [queued]>
[2024-05-23T00:49:41.059+0000] {taskinstance.py:2306} INFO - Starting attempt 1 of 1
[2024-05-23T00:49:41.096+0000] {taskinstance.py:2330} INFO - Executing <Task(PostgresOperator): load_task> on 2024-05-22 22:09:25.534916+00:00
[2024-05-23T00:49:41.110+0000] {warnings.py:110} WARNING - /home/***/.local/lib/python3.12/site-packages/***/task/task_runner/standard_task_runner.py:61: DeprecationWarning: This process (pid=3053) is multi-threaded, use of fork() may lead to deadlocks in the child.
  pid = os.fork()

[2024-05-23T00:49:41.113+0000] {standard_task_runner.py:63} INFO - Started process 3077 to run task
[2024-05-23T00:49:41.112+0000] {standard_task_runner.py:90} INFO - Running: ['***', 'tasks', 'run', 'kaggle_dataset', 'load_task', 'manual__2024-05-22T22:09:25.534916+00:00', '--job-id', '24', '--raw', '--subdir', 'DAGS_FOLDER/kaggle_dataset.py', '--cfg-path', '/tmp/tmp5cod8bhj']
[2024-05-23T00:49:41.117+0000] {standard_task_runner.py:91} INFO - Job 24: Subtask load_task
[2024-05-23T00:49:41.266+0000] {task_command.py:426} INFO - Running <TaskInstance: kaggle_dataset.load_task manual__2024-05-22T22:09:25.534916+00:00 [running]> on host 3943db1ddae8
[2024-05-23T00:49:41.792+0000] {taskinstance.py:2648} INFO - Exporting env vars: AIRFLOW_CTX_DAG_OWNER='***' AIRFLOW_CTX_DAG_ID='kaggle_dataset' AIRFLOW_CTX_TASK_ID='load_task' AIRFLOW_CTX_EXECUTION_DATE='2024-05-22T22:09:25.534916+00:00' AIRFLOW_CTX_TRY_NUMBER='1' AIRFLOW_CTX_DAG_RUN_ID='manual__2024-05-22T22:09:25.534916+00:00'
[2024-05-23T00:49:41.833+0000] {taskinstance.py:430} INFO - ::endgroup::
[2024-05-23T00:49:41.923+0000] {sql.py:276} INFO - Executing: EXECUTE sp_load_fact_global_economic_ind
[2024-05-23T00:49:41.954+0000] {base.py:84} INFO - Using connection ID 'postgrest_projects' for task execution.
[2024-05-23T00:49:41.977+0000] {base.py:84} INFO - Using connection ID 'postgrest_projects' for task execution.
[2024-05-23T00:49:41.982+0000] {taskinstance.py:441} INFO - ::group::Post task execution logs
[2024-05-23T00:49:41.985+0000] {taskinstance.py:2905} ERROR - Task failed with exception
Traceback (most recent call last):
  File "/home/airflow/.local/lib/python3.12/site-packages/airflow/models/taskinstance.py", line 465, in _execute_task
    result = _execute_callable(context=context, **execute_callable_kwargs)
             ^^^^^^^^^^^^^^^^^^^^^^^^^^^^^^^^^^^^^^^^^^^^^^^^^^^^^^^^^^^^^
  File "/home/airflow/.local/lib/python3.12/site-packages/airflow/models/taskinstance.py", line 432, in _execute_callable
    return execute_callable(context=context, **execute_callable_kwargs)
           ^^^^^^^^^^^^^^^^^^^^^^^^^^^^^^^^^^^^^^^^^^^^^^^^^^^^^^^^^^^^
  File "/home/airflow/.local/lib/python3.12/site-packages/airflow/models/baseoperator.py", line 400, in wrapper
    return func(self, *args, **kwargs)
           ^^^^^^^^^^^^^^^^^^^^^^^^^^^
  File "/home/airflow/.local/lib/python3.12/site-packages/airflow/providers/common/sql/operators/sql.py", line 282, in execute
    output = hook.run(
             ^^^^^^^^^
  File "/home/airflow/.local/lib/python3.12/site-packages/airflow/providers/common/sql/hooks/sql.py", line 411, in run
    with closing(self.get_conn()) as conn:
                 ^^^^^^^^^^^^^^^
  File "/home/airflow/.local/lib/python3.12/site-packages/airflow/providers/postgres/hooks/postgres.py", line 161, in get_conn
    self.conn = psycopg2.connect(**conn_args)
                ^^^^^^^^^^^^^^^^^^^^^^^^^^^^^
  File "/home/airflow/.local/lib/python3.12/site-packages/psycopg2/__init__.py", line 122, in connect
    conn = _connect(dsn, connection_factory=connection_factory, **kwasync)
           ^^^^^^^^^^^^^^^^^^^^^^^^^^^^^^^^^^^^^^^^^^^^^^^^^^^^^^^^^^^^^^^
psycopg2.OperationalError: connection to server at "localhost" (::1), port 5432 failed: Connection refused
	Is the server running on that host and accepting TCP/IP connections?
connection to server at "localhost" (127.0.0.1), port 5432 failed: Connection refused
	Is the server running on that host and accepting TCP/IP connections?

[2024-05-23T00:49:42.014+0000] {taskinstance.py:1206} INFO - Marking task as FAILED. dag_id=kaggle_dataset, task_id=load_task, run_id=manual__2024-05-22T22:09:25.534916+00:00, execution_date=20240522T220925, start_date=20240523T004941, end_date=20240523T004942
[2024-05-23T00:49:42.053+0000] {standard_task_runner.py:110} ERROR - Failed to execute job 24 for task load_task (connection to server at "localhost" (::1), port 5432 failed: Connection refused
	Is the server running on that host and accepting TCP/IP connections?
connection to server at "localhost" (127.0.0.1), port 5432 failed: Connection refused
	Is the server running on that host and accepting TCP/IP connections?
; 3077)
[2024-05-23T00:49:42.100+0000] {local_task_job_runner.py:240} INFO - Task exited with return code 1
[2024-05-23T00:49:42.128+0000] {warnings.py:110} WARNING - /home/***/.local/lib/python3.12/site-packages/***/models/baseoperator.py:1296: AirflowProviderDeprecationWarning: Call to deprecated class PostgresOperator. (Please use `***.providers.common.sql.operators.sql.SQLExecuteQueryOperator`.Also, you can provide `hook_params={'schema': <database>}`.)
  result = cls.__new__(cls)

[2024-05-23T00:49:42.173+0000] {taskinstance.py:3498} INFO - 0 downstream tasks scheduled from follow-on schedule check
[2024-05-23T00:49:42.187+0000] {local_task_job_runner.py:222} INFO - ::endgroup::
